<?xml version="1.0"?>
<robot name="my_robot">
  <!-- TODO: Create a base_link with visual, collision, and inertial properties -->
  <link name="base_link">
    <visual>
      <geometry>
        <box size="0.4 0.3 0.1"/>
      </geometry>
      <material name="blue">
        <color rgba="0 0 0.8 1"/>
      </material>
    </visual>
    <collision>
      <geometry>
        <box size="0.4 0.3 0.1"/>
      </geometry>
    </collision>
    <inertial>
      <mass value="1.0"/>
      <origin xyz="0 0 0" rpy="0 0 0"/>
      <inertia ixx="0.01" ixy="0.0" ixz="0.0" iyy="0.01" iyz="0.0" izz="0.01"/>
    </inertial>
  </link>

  <!-- Add cillinder on top of the robot-->
  <link name="top_link">
    <visual>
      <geometry>
        <cylinder radius="0.1" length="0.07"/>
      </geometry>
      <material name="yellow">
        <color rgba="0.8 0.8 0.0 1"/>
      </material>
    </visual>
    <collision>
      <geometry>
        <cylinder radius="0.1" length="0.07"/>
      </geometry>
    </collision>
    <inertial>
      <mass value="1.0"/>
      <origin xyz="0 0 0" rpy="0 0 0"/>
      <inertia ixx="0.01" ixy="0.0" ixz="0.0" iyy="0.01" iyz="0.0" izz="0.01"/>
    </inertial>
  </link>
  
  <!-- Right Wheel -->
  <link name="right_wheel">
    <visual>
      <!-- Use cylinder that's SHORTER but WIDER to show the correct orientation -->
      <geometry>
        <cylinder radius="0.08" length="0.05"/>
      </geometry>
      <material name="black">
        <color rgba="0 0 0 1"/>
      </material>
      <!-- No rotation, leaving it flat -->
      <origin xyz="0 0 0" rpy="0 0 0"/>
    </visual>
    <collision>
      <geometry>
        <cylinder radius="0.08" length="0.05"/>
      </geometry>
      <origin xyz="0 0 0" rpy="0 0 0"/>
    </collision>
    <inertial>
      <mass value="0.1"/>
      <origin xyz="0 0 0" rpy="0 0 0"/>
      <inertia ixx="0.00015" ixy="0.0" ixz="0.0" iyy="0.00015" iyz="0.0" izz="0.0001"/>
    </inertial>
  </link>

  <!-- Left Wheel -->
  <link name="left_wheel">
    <visual>
      <!-- Use cylinder that's SHORTER but WIDER to show the correct orientation -->
      <geometry>
        <cylinder radius="0.08" length="0.05"/>
      </geometry>
      <material name="black">
        <color rgba="0 0 0 1"/>
      </material>
      <!-- No rotation, leaving it flat -->
      <origin xyz="0 0 0" rpy="0 0 0"/>
    </visual>
    <collision>
      <geometry>
        <cylinder radius="0.08" length="0.05"/>
      </geometry>
      <origin xyz="0 0 0" rpy="0 0 0"/>
    </collision>
    <inertial>
      <mass value="0.1"/>
      <origin xyz="0 0 0" rpy="0 0 0"/>
      <inertia ixx="0.00015" ixy="0.0" ixz="0.0" iyy="0.00015" iyz="0.0" izz="0.0001"/>
    </inertial>
  </link>

  <!-- Caster Wheel -->
  <link name="caster_wheel">
    <visual>
      <geometry>
        <sphere radius="0.035"/>
      </geometry>
      <material name="grey">
        <color rgba="0.5 0.5 0.5 1"/>
      </material>
    </visual>
    <collision>
      <geometry>
        <sphere radius="0.035"/>
      </geometry>
    </collision>
    <inertial>
      <mass value="0.05"/>
      <origin xyz="0 0 0" rpy="0 0 0"/>
      <inertia ixx="0.00002" ixy="0.0" ixz="0.0" iyy="0.00002" iyz="0.0" izz="0.00002"/>
    </inertial>
  </link>

  <joint name="top_link_joint" type="fixed">
    <parent link="base_link"/>
    <child link="top_link"/>
    <origin xyz="0 0 0.085" rpy="0 0 0"/>
  </joint>

  <!-- Right Wheel Joint -->
  <joint name="right_wheel_joint" type="continuous">
    <parent link="base_link"/>
    <child link="right_wheel"/>
    <!-- Position the wheel on its edge -->
    <origin xyz="-0.15 -0.17 0" rpy="1.5707 0 0"/>
    <!-- Rotate around Z axis as viewed from wheel's perspective -->
    <axis xyz="0 0 -1"/>
    <dynamics damping="0.01" friction="0.0"/>
  </joint>

  <!-- Left Wheel Joint -->
  <joint name="left_wheel_joint" type="continuous">
    <parent link="base_link"/>
    <child link="left_wheel"/>
    <!-- Position the wheel on its edge -->
    <origin xyz="-0.15 0.17 0" rpy="1.5707 0 0"/>
    <!-- Rotate around Z axis as viewed from wheel's perspective -->
    <axis xyz="0 0 -1"/>
    <dynamics damping="0.01" friction="0.0"/>
  </joint>

  <!-- Caster Joint -->
  <joint name="caster_joint" type="fixed">
    <parent link="base_link"/>
    <child link="caster_wheel"/>
    <origin xyz="0.12 0 -0.0325" rpy="0 0 0"/>
  </joint>

  <!-- TODO: Create left and right camera links -->

  <link name="right_camera_link">
    <visual>
      <geometry>
        <box size="0.05 0.05 0.05"/>
      </geometry>
      <material name="red">
        <color rgba="1 0 0 1"/>
      </material>
    </visual>
    <collision>
      <geometry>
        <box size="0.05 0.05 0.05"/>
      </geometry>
    </collision>
    <inertial>
      <mass value="0.01"/>
      <origin xyz="0 0 0" rpy="0 0 0"/>
      <inertia ixx="0.0001" ixy="0.0" ixz="0.0" iyy="0.0001" iyz="0.0" izz="0.0001"/>
    </inertial>
  </link>

  <link name="left_camera_link">
    <visual>
      <geometry>
        <box size="0.05 0.05 0.05"/>
      </geometry>
      <material name="red">
        <color rgba="1 0 0 1"/>
      </material>
    </visual>
    <collision>
      <geometry>
        <box size="0.05 0.05 0.05"/>
      </geometry>
    </collision>
    <inertial>
      <mass value="0.01"/>
      <origin xyz="0 0 0" rpy="0 0 0"/>
      <inertia ixx="0.0001" ixy="0.0" ixz="0.0" iyy="0.0001" iyz="0.0" izz="0.0001"/>
    </inertial>
  </link>


  <!-- TODO: Create left and right camera optical links -->

  <link name="right_camera_link_optical">
    <inertial>
      <mass value="0.001"/>
      <origin xyz="0 0 0" rpy="0 0 0"/>
      <inertia ixx="0.00001" ixy="0.0" ixz="0.0" iyy="0.00001" iyz="0.0" izz="0.00001"/>
    </inertial>
  </link>

  <link name="left_camera_link_optical">
    <inertial>
      <mass value="0.001"/>
      <origin xyz="0 0 0" rpy="0 0 0"/>
      <inertia ixx="0.00001" ixy="0.0" ixz="0.0" iyy="0.00001" iyz="0.0" izz="0.00001"/>
    </inertial>
  </link>

  <!-- TODO: Create fixed joints for the cameras (connecting to base_link) -->

  <joint name="left_camera_joint" type="fixed">
    <parent link="base_link"/>
    <child link="left_camera_link"/>
    <origin xyz="0.15 0.05 0.075" rpy="0 0 0"/>
  </joint>

  <joint name="right_camera_joint" type="fixed">
    <parent link="base_link"/>
    <child link="right_camera_link"/>
    <origin xyz="0.15 -0.05 0.075" rpy="0 0 0"/>
  </joint>

  <!-- TODO: Create fixed joints for the camera optical frames (connecting to respective camera links) -->

  <joint name="right_camera_optical_joint" type="fixed">
    <parent link="right_camera_link"/>
    <child link="right_camera_link_optical"/>
    <origin xyz="0 0 0" rpy="-1.5707 0 -1.5707"/>
  </joint>

  <joint name="left_camera_optical_joint" type="fixed">
    <parent link="left_camera_link"/>
    <child link="left_camera_link_optical"/>
    <origin xyz="0 0 0" rpy="-1.5707 0 -1.5707"/>
  </joint>
</robot>